Unhandled exception in curses UI:

Traceback (most recent call last):
  File "C:\Users\7tujo\Programming\text-adventure\gameplay.py", line 212, in <module>
    curses.wrapper(lambda stdscr: main(stdscr, initial_save_code))
    ~~~~~~~~~~~~~~^^^^^^^^^^^^^^^^^^^^^^^^^^^^^^^^^^^^^^^^^^^^^^^^
  File "C:\Program Files\WindowsApps\PythonSoftwareFoundation.Python.3.13_3.13.2544.0_x64__qbz5n2kfra8p0\Lib\curses\__init__.py", line 94, in wrapper
    return func(stdscr, *args, **kwds)
  File "C:\Users\7tujo\Programming\text-adventure\gameplay.py", line 212, in <lambda>
    curses.wrapper(lambda stdscr: main(stdscr, initial_save_code))
                                  ~~~~^^^^^^^^^^^^^^^^^^^^^^^^^^^
  File "C:\Users\7tujo\Programming\text-adventure\gameplay.py", line 119, in main
    player_state["status_effects"].append("Poisoned")
    ^^^^^^^^^^^^^^^^^^^^^^^^^^^^^^^^^^^^^
AttributeError: 'dict' object has no attribute 'append'
